<?xml version="1.0" encoding="UTF-8"?>
<testng-results ignored="0" total="3" passed="0" failed="3" skipped="0">
  <reporter-output>
  </reporter-output>
  <suite started-at="2023-09-17T13:14:50 IST" name="Default suite" finished-at="2023-09-17T13:15:27 IST" duration-ms="37525">
    <groups>
    </groups>
    <test started-at="2023-09-17T13:14:50 IST" name="Default test" finished-at="2023-09-17T13:15:27 IST" duration-ms="37525">
      <class name="com.hrm.testcases.TC_006_DataDrivenTestingFor3FailedAttempts">
        <test-method is-config="true" signature="setupBeforeTest()[pri:0, instance:com.hrm.testcases.TC_006_DataDrivenTestingFor3FailedAttempts@7c541c15]" started-at="2023-09-17T13:14:50 IST" name="setupBeforeTest" finished-at="2023-09-17T13:15:11 IST" duration-ms="21018" status="PASS">
          <reporter-output>
          </reporter-output>
        </test-method> <!-- setupBeforeTest -->
        <test-method signature="verifyLoginWithThreeWrongAttempts(java.lang.String,java.lang.String)[pri:0, instance:com.hrm.testcases.TC_006_DataDrivenTestingFor3FailedAttempts@7c541c15]" started-at="2023-09-17T13:15:11 IST" name="verifyLoginWithThreeWrongAttempts" data-provider="multiple-user-credentials" finished-at="2023-09-17T13:15:19 IST" duration-ms="8295" status="FAIL">
          <params>
            <param index="0">
              <value>
                <![CDATA[Admin1]]>
              </value>
            </param>
            <param index="1">
              <value>
                <![CDATA[pass1]]>
              </value>
            </param>
          </params>
          <exception class="java.lang.AssertionError">
            <message>
              <![CDATA[The following asserts failed:
expected [true] but found [false]]]>
            </message>
            <full-stacktrace>
              <![CDATA[java.lang.AssertionError: The following asserts failed:
expected [true] but found [false]
at org.testng.asserts.SoftAssert.assertAll(SoftAssert.java:46)
at org.testng.asserts.SoftAssert.assertAll(SoftAssert.java:30)
at com.hrm.testcases.TC_006_DataDrivenTestingFor3FailedAttempts.verifyLoginWithThreeWrongAttempts(TC_006_DataDrivenTestingFor3FailedAttempts.java:42)
at java.base/jdk.internal.reflect.DirectMethodHandleAccessor.invoke(DirectMethodHandleAccessor.java:104)
at java.base/java.lang.reflect.Method.invoke(Method.java:578)
at org.testng.internal.invokers.MethodInvocationHelper.invokeMethod(MethodInvocationHelper.java:139)
at org.testng.internal.invokers.TestInvoker.invokeMethod(TestInvoker.java:664)
at org.testng.internal.invokers.TestInvoker.invokeTestMethod(TestInvoker.java:227)
at org.testng.internal.invokers.MethodRunner.runInSequence(MethodRunner.java:50)
at org.testng.internal.invokers.TestInvoker$MethodInvocationAgent.invoke(TestInvoker.java:957)
at org.testng.internal.invokers.TestInvoker.invokeTestMethods(TestInvoker.java:200)
at org.testng.internal.invokers.TestMethodWorker.invokeTestMethods(TestMethodWorker.java:148)
at org.testng.internal.invokers.TestMethodWorker.run(TestMethodWorker.java:128)
at java.base/java.util.ArrayList.forEach(ArrayList.java:1511)
at org.testng.TestRunner.privateRun(TestRunner.java:848)
at org.testng.TestRunner.run(TestRunner.java:621)
at org.testng.SuiteRunner.runTest(SuiteRunner.java:443)
at org.testng.SuiteRunner.runSequentially(SuiteRunner.java:437)
at org.testng.SuiteRunner.privateRun(SuiteRunner.java:397)
at org.testng.SuiteRunner.run(SuiteRunner.java:336)
at org.testng.SuiteRunnerWorker.runSuite(SuiteRunnerWorker.java:52)
at org.testng.SuiteRunnerWorker.run(SuiteRunnerWorker.java:95)
at org.testng.TestNG.runSuitesSequentially(TestNG.java:1280)
at org.testng.TestNG.runSuitesLocally(TestNG.java:1200)
at org.testng.TestNG.runSuites(TestNG.java:1114)
at org.testng.TestNG.run(TestNG.java:1082)
at org.testng.remote.AbstractRemoteTestNG.run(AbstractRemoteTestNG.java:115)
at org.testng.remote.RemoteTestNG.initAndRun(RemoteTestNG.java:251)
at org.testng.remote.RemoteTestNG.main(RemoteTestNG.java:77)
]]>
            </full-stacktrace>
          </exception> <!-- java.lang.AssertionError -->
          <reporter-output>
          </reporter-output>
        </test-method> <!-- verifyLoginWithThreeWrongAttempts -->
        <test-method signature="verifyLoginWithThreeWrongAttempts(java.lang.String,java.lang.String)[pri:0, instance:com.hrm.testcases.TC_006_DataDrivenTestingFor3FailedAttempts@7c541c15]" started-at="2023-09-17T13:15:19 IST" name="verifyLoginWithThreeWrongAttempts" data-provider="multiple-user-credentials" finished-at="2023-09-17T13:15:21 IST" duration-ms="1814" status="FAIL">
          <params>
            <param index="0">
              <value>
                <![CDATA[Admin2]]>
              </value>
            </param>
            <param index="1">
              <value>
                <![CDATA[pass2]]>
              </value>
            </param>
          </params>
          <exception class="java.lang.AssertionError">
            <message>
              <![CDATA[The following asserts failed:
expected [true] but found [false],
expected [true] but found [false]]]>
            </message>
            <full-stacktrace>
              <![CDATA[java.lang.AssertionError: The following asserts failed:
expected [true] but found [false],
expected [true] but found [false]
at org.testng.asserts.SoftAssert.assertAll(SoftAssert.java:46)
at org.testng.asserts.SoftAssert.assertAll(SoftAssert.java:30)
at com.hrm.testcases.TC_006_DataDrivenTestingFor3FailedAttempts.verifyLoginWithThreeWrongAttempts(TC_006_DataDrivenTestingFor3FailedAttempts.java:42)
at java.base/jdk.internal.reflect.DirectMethodHandleAccessor.invoke(DirectMethodHandleAccessor.java:104)
at java.base/java.lang.reflect.Method.invoke(Method.java:578)
at org.testng.internal.invokers.MethodInvocationHelper.invokeMethod(MethodInvocationHelper.java:139)
at org.testng.internal.invokers.TestInvoker.invokeMethod(TestInvoker.java:664)
at org.testng.internal.invokers.TestInvoker.invokeTestMethod(TestInvoker.java:227)
at org.testng.internal.invokers.MethodRunner.runInSequence(MethodRunner.java:50)
at org.testng.internal.invokers.TestInvoker$MethodInvocationAgent.invoke(TestInvoker.java:957)
at org.testng.internal.invokers.TestInvoker.invokeTestMethods(TestInvoker.java:200)
at org.testng.internal.invokers.TestMethodWorker.invokeTestMethods(TestMethodWorker.java:148)
at org.testng.internal.invokers.TestMethodWorker.run(TestMethodWorker.java:128)
at java.base/java.util.ArrayList.forEach(ArrayList.java:1511)
at org.testng.TestRunner.privateRun(TestRunner.java:848)
at org.testng.TestRunner.run(TestRunner.java:621)
at org.testng.SuiteRunner.runTest(SuiteRunner.java:443)
at org.testng.SuiteRunner.runSequentially(SuiteRunner.java:437)
at org.testng.SuiteRunner.privateRun(SuiteRunner.java:397)
at org.testng.SuiteRunner.run(SuiteRunner.java:336)
at org.testng.SuiteRunnerWorker.runSuite(SuiteRunnerWorker.java:52)
at org.testng.SuiteRunnerWorker.run(SuiteRunnerWorker.java:95)
at org.testng.TestNG.runSuitesSequentially(TestNG.java:1280)
at org.testng.TestNG.runSuitesLocally(TestNG.java:1200)
at org.testng.TestNG.runSuites(TestNG.java:1114)
at org.testng.TestNG.run(TestNG.java:1082)
at org.testng.remote.AbstractRemoteTestNG.run(AbstractRemoteTestNG.java:115)
at org.testng.remote.RemoteTestNG.initAndRun(RemoteTestNG.java:251)
at org.testng.remote.RemoteTestNG.main(RemoteTestNG.java:77)
]]>
            </full-stacktrace>
          </exception> <!-- java.lang.AssertionError -->
          <reporter-output>
          </reporter-output>
        </test-method> <!-- verifyLoginWithThreeWrongAttempts -->
        <test-method signature="verifyLoginWithThreeWrongAttempts(java.lang.String,java.lang.String)[pri:0, instance:com.hrm.testcases.TC_006_DataDrivenTestingFor3FailedAttempts@7c541c15]" started-at="2023-09-17T13:15:21 IST" name="verifyLoginWithThreeWrongAttempts" data-provider="multiple-user-credentials" finished-at="2023-09-17T13:15:23 IST" duration-ms="1596" status="FAIL">
          <params>
            <param index="0">
              <value>
                <![CDATA[Admin3]]>
              </value>
            </param>
            <param index="1">
              <value>
                <![CDATA[pass3]]>
              </value>
            </param>
          </params>
          <exception class="java.lang.AssertionError">
            <message>
              <![CDATA[The following asserts failed:
expected [true] but found [false],
expected [true] but found [false],
expected [true] but found [false]]]>
            </message>
            <full-stacktrace>
              <![CDATA[java.lang.AssertionError: The following asserts failed:
expected [true] but found [false],
expected [true] but found [false],
expected [true] but found [false]
at org.testng.asserts.SoftAssert.assertAll(SoftAssert.java:46)
at org.testng.asserts.SoftAssert.assertAll(SoftAssert.java:30)
at com.hrm.testcases.TC_006_DataDrivenTestingFor3FailedAttempts.verifyLoginWithThreeWrongAttempts(TC_006_DataDrivenTestingFor3FailedAttempts.java:42)
at java.base/jdk.internal.reflect.DirectMethodHandleAccessor.invoke(DirectMethodHandleAccessor.java:104)
at java.base/java.lang.reflect.Method.invoke(Method.java:578)
at org.testng.internal.invokers.MethodInvocationHelper.invokeMethod(MethodInvocationHelper.java:139)
at org.testng.internal.invokers.TestInvoker.invokeMethod(TestInvoker.java:664)
at org.testng.internal.invokers.TestInvoker.invokeTestMethod(TestInvoker.java:227)
at org.testng.internal.invokers.MethodRunner.runInSequence(MethodRunner.java:50)
at org.testng.internal.invokers.TestInvoker$MethodInvocationAgent.invoke(TestInvoker.java:957)
at org.testng.internal.invokers.TestInvoker.invokeTestMethods(TestInvoker.java:200)
at org.testng.internal.invokers.TestMethodWorker.invokeTestMethods(TestMethodWorker.java:148)
at org.testng.internal.invokers.TestMethodWorker.run(TestMethodWorker.java:128)
at java.base/java.util.ArrayList.forEach(ArrayList.java:1511)
at org.testng.TestRunner.privateRun(TestRunner.java:848)
at org.testng.TestRunner.run(TestRunner.java:621)
at org.testng.SuiteRunner.runTest(SuiteRunner.java:443)
at org.testng.SuiteRunner.runSequentially(SuiteRunner.java:437)
at org.testng.SuiteRunner.privateRun(SuiteRunner.java:397)
at org.testng.SuiteRunner.run(SuiteRunner.java:336)
at org.testng.SuiteRunnerWorker.runSuite(SuiteRunnerWorker.java:52)
at org.testng.SuiteRunnerWorker.run(SuiteRunnerWorker.java:95)
at org.testng.TestNG.runSuitesSequentially(TestNG.java:1280)
at org.testng.TestNG.runSuitesLocally(TestNG.java:1200)
at org.testng.TestNG.runSuites(TestNG.java:1114)
at org.testng.TestNG.run(TestNG.java:1082)
at org.testng.remote.AbstractRemoteTestNG.run(AbstractRemoteTestNG.java:115)
at org.testng.remote.RemoteTestNG.initAndRun(RemoteTestNG.java:251)
at org.testng.remote.RemoteTestNG.main(RemoteTestNG.java:77)
]]>
            </full-stacktrace>
          </exception> <!-- java.lang.AssertionError -->
          <reporter-output>
          </reporter-output>
        </test-method> <!-- verifyLoginWithThreeWrongAttempts -->
        <test-method is-config="true" signature="tearDown()[pri:0, instance:com.hrm.testcases.TC_006_DataDrivenTestingFor3FailedAttempts@7c541c15]" started-at="2023-09-17T13:15:23 IST" name="tearDown" finished-at="2023-09-17T13:15:27 IST" duration-ms="4557" status="PASS">
          <reporter-output>
          </reporter-output>
        </test-method> <!-- tearDown -->
      </class> <!-- com.hrm.testcases.TC_006_DataDrivenTestingFor3FailedAttempts -->
    </test> <!-- Default test -->
  </suite> <!-- Default suite -->
</testng-results>
